Workbook

Sheet Summary
A1: Mouza Dura joint layout · plot ledger
A2: Partners MPR, MGR, MJR, MDR share equally (25% each). Sales by MKR. Blue cells are inputs; black cells are calculated.
A3: Contract rate (₹ per sq ft, 2022 agreement) | B3: 800
A5: LAND
A6: Saleable area (sq ft) | B6: =SUM(Plots!F2:F62)-SUMIFS(Plots!F2:F62,Plots!G2:G62,"Gifted")-SUMIFS(Plots!F2:F62,Plots!G2:G62,"Can't be sold") -> 45551.4
A7: Sold (sq ft) | B7: =SUM(Plots!H2:H62) -> 38394.5
A8: Sold, valued at the rate (₹) | B8: =B7*$B$3 -> 30715600
A9: Yet to be sold (sq ft) | B9: =SUM(Plots!I2:I62) -> 6977.4
A10: Yet to be sold, valued at the rate (₹) | B10: =B9*$B$3 -> 5581920
A11: Gifted (sq ft) | B11: =SUMIFS(Plots!F2:F62,Plots!G2:G62,"Gifted") -> 8400
A12: Can't be sold (sq ft) | B12: =SUMIFS(Plots!F2:F62,Plots!G2:G62,"Can't be sold") -> 2044.81
A13: MONEY
A14: Owed to partners for land sold (₹) | B14: =SUM(Plots!K2:K62) -> 30715600
A15: Paid to partners against plots (₹) | B15: =SUM(Plots!L2:L62) -> 28776800
A16: Still due from MKR on land sold (₹) | B16: =B14-B15 -> 1938800
A17: Token advance and other payments (₹) | B17: =SUM('Other payments'!C2:C200) -> 2000000
A18: Overall balance (₹) [positive = MKR owes, negative = MKR ahead] | B18: =B16-B17 -> -61200
A19: PER PARTNER (÷ 4)
A20: Owed per partner (₹) | B20: =B14/4 -> 7678900
A21: Received per partner, incl. advance (₹) | B21: =(B15+B17)/4 -> 7694200
A22: Balance per partner (₹) | B22: =B18/4 -> -15300

Sheet Plots
A1: Map no | B1: Survey plot | C1: Size (as written) | D1: Length (ft) | E1: Breadth (ft) | F1: Area (sq ft) | G1: Status | H1: Sq ft sold | I1: Unsold sq ft | J1: Tranche | K1: Owed to partners (₹) | L1: Paid to partners (₹) | M1: Balance due from MKR (₹) | N1: Unsold value at rate (₹) | O1: Buyer | P1: Sale date | Q1: Notes
A2: 1 | B2: 206 | C2: Avg(7,13.5)XAvg(82,86.5) | D2: 84.25 | E2: 10.25 | F2: 863.56 | G2: Can't be sold | I2: =IF(G2="Unsold",F2,IF(G2="Part-sold",F2-H2,0)) -> 0 | K2: =IF(OR(G2="Sold",G2="Part-sold"),H2*Summary!$B$3,0) -> 0 | M2: =K2-N(L2) -> 0 | N2: =I2*Summary!$B$3 -> 0 | Q2: Marked "Cant be sold" in the Excel of 10 Oct 2026.
A3: 2 | B3: 206 | C3: 15XAvg(86.5,91) | D3: 88.75 | E3: 15 | F3: 1331.25 | G3: Sold | H3: 1331 | I3: =IF(G3="Unsold",F3,IF(G3="Part-sold",F3-H3,0)) -> 0 | J3: 1 | K3: =IF(OR(G3="Sold",G3="Part-sold"),H3*Summary!$B$3,0) -> 1064800 | L3: 914777 | M3: =K3-N(L3) -> 150023 | N3: =I3*Summary!$B$3 -> 0 | Q3: Part of Tranche 1 (paid as one lump sum; split here by sq ft sold).
A4: 3 | B4: 206 | C4: 15XAvg(91, 91.5) | D4: 91.25 | E4: 15 | F4: 1368.75 | G4: Sold | H4: 1365 | I4: =IF(G4="Unsold",F4,IF(G4="Part-sold",F4-H4,0)) -> 0 | J4: 1 | K4: =IF(OR(G4="Sold",G4="Part-sold"),H4*Summary!$B$3,0) -> 1092000 | L4: 938144 | M4: =K4-N(L4) -> 153856 | N4: =I4*Summary!$B$3 -> 0 | Q4: Part of Tranche 1 (paid as one lump sum; split here by sq ft sold).
A5: 4 | B5: 206 | C5: 15X60 | D5: 60 | E5: 15 | F5: 900 | G5: Sold | H5: 900 | I5: =IF(G5="Unsold",F5,IF(G5="Part-sold",F5-H5,0)) -> 0 | J5: 1 | K5: =IF(OR(G5="Sold",G5="Part-sold"),H5*Summary!$B$3,0) -> 720000 | L5: 618557 | M5: =K5-N(L5) -> 101443 | N5: =I5*Summary!$B$3 -> 0 | Q5: To check: Excel cell note: Deb dada's notebook entry is 1,376; doesn't match when added up Part of Tranche 1 (paid as one lump sum; split here by sq ft sold).
A6: 5 | B6: 206 | C6: 15X60 | D6: 60 | E6: 15 | F6: 900 | G6: Sold | H6: 900 | I6: =IF(G6="Unsold",F6,IF(G6="Part-sold",F6-H6,0)) -> 0 | J6: 1 | K6: =IF(OR(G6="Sold",G6="Part-sold"),H6*Summary!$B$3,0) -> 720000 | L6: 618557 | M6: =K6-N(L6) -> 101443 | N6: =I6*Summary!$B$3 -> 0 | Q6: Part of Tranche 1 (paid as one lump sum; split here by sq ft sold).
A7: 6 | B7: 206 | C7: 15X60 | D7: 60 | E7: 15 | F7: 900 | G7: Sold | H7: 900 | I7: =IF(G7="Unsold",F7,IF(G7="Part-sold",F7-H7,0)) -> 0 | J7: 6 | K7: =IF(OR(G7="Sold",G7="Part-sold"),H7*Summary!$B$3,0) -> 720000 | L7: 608000 | M7: =K7-N(L7) -> 112000 | N7: =I7*Summary!$B$3 -> 0 | Q7: ₹28,000 per partner (₹1,12,000 in all) still to be paid by MKR (per Venu, 17 Oct 2026). The Excel shows the full ₹7,20,000 as received.
A8: 7 | B8: 206 | C8: 15X60 | D8: 60 | E8: 15 | F8: 900 | G8: Sold | H8: 900 | I8: =IF(G8="Unsold",F8,IF(G8="Part-sold",F8-H8,0)) -> 0 | J8: 6 | K8: =IF(OR(G8="Sold",G8="Part-sold"),H8*Summary!$B$3,0) -> 720000 | L8: 720000 | M8: =K8-N(L8) -> 0 | N8: =I8*Summary!$B$3 -> 0
A9: 8 | B9: 206 | C9: 15X60 | D9: 60 | E9: 15 | F9: 900 | G9: Sold | H9: 900 | I9: =IF(G9="Unsold",F9,IF(G9="Part-sold",F9-H9,0)) -> 0 | J9: 6 | K9: =IF(OR(G9="Sold",G9="Part-sold"),H9*Summary!$B$3,0) -> 720000 | L9: 720000 | M9: =K9-N(L9) -> 0 | N9: =I9*Summary!$B$3 -> 0
A10: 9 | B10: 206 | C10: 15X60 | D10: 60 | E10: 15 | F10: 900 | G10: Sold | H10: 900 | I10: =IF(G10="Unsold",F10,IF(G10="Part-sold",F10-H10,0)) -> 0 | K10: =IF(OR(G10="Sold",G10="Part-sold"),H10*Summary!$B$3,0) -> 720000 | L10: 720000 | M10: =K10-N(L10) -> 0 | N10: =I10*Summary!$B$3 -> 0
A11: 10 | B11: 206 | C11: 33.3XAvg(90, 89,95) | D11: 91.33 | E11: 33.3 | F11: 3041.4 | G11: Unsold | I11: =IF(G11="Unsold",F11,IF(G11="Part-sold",F11-H11,0)) -> 3041.4 | K11: =IF(OR(G11="Sold",G11="Part-sold"),H11*Summary!$B$3,0) -> 0 | M11: =K11-N(L11) -> 0 | N11: =I11*Summary!$B$3 -> 2433120
A12: 11 | B12: 206 | C12: 15X70 | D12: 70 | E12: 15 | F12: 1050 | G12: Gifted | I12: =IF(G12="Unsold",F12,IF(G12="Part-sold",F12-H12,0)) -> 0 | K12: =IF(OR(G12="Sold",G12="Part-sold"),H12*Summary!$B$3,0) -> 0 | M12: =K12-N(L12) -> 0 | N12: =I12*Summary!$B$3 -> 0
A13: 12 | B13: 206 | C13: 15X70 | D13: 70 | E13: 15 | F13: 1050 | G13: Gifted | I13: =IF(G13="Unsold",F13,IF(G13="Part-sold",F13-H13,0)) -> 0 | K13: =IF(OR(G13="Sold",G13="Part-sold"),H13*Summary!$B$3,0) -> 0 | M13: =K13-N(L13) -> 0 | N13: =I13*Summary!$B$3 -> 0
A14: 13 | B14: 206 | C14: 15X70 | D14: 70 | E14: 15 | F14: 1050 | G14: Gifted | I14: =IF(G14="Unsold",F14,IF(G14="Part-sold",F14-H14,0)) -> 0 | K14: =IF(OR(G14="Sold",G14="Part-sold"),H14*Summary!$B$3,0) -> 0 | M14: =K14-N(L14) -> 0 | N14: =I14*Summary!$B$3 -> 0
A15: 14 | B15: 206 | C15: 15X70 | D15: 70 | E15: 15 | F15: 1050 | G15: Gifted | I15: =IF(G15="Unsold",F15,IF(G15="Part-sold",F15-H15,0)) -> 0 | K15: =IF(OR(G15="Sold",G15="Part-sold"),H15*Summary!$B$3,0) -> 0 | M15: =K15-N(L15) -> 0 | N15: =I15*Summary!$B$3 -> 0
A16: 15 | B16: 206 | C16: 15X70 | D16: 70 | E16: 15 | F16: 1050 | G16: Gifted | I16: =IF(G16="Unsold",F16,IF(G16="Part-sold",F16-H16,0)) -> 0 | K16: =IF(OR(G16="Sold",G16="Part-sold"),H16*Summary!$B$3,0) -> 0 | M16: =K16-N(L16) -> 0 | N16: =I16*Summary!$B$3 -> 0
A17: 16 | B17: 206 | C17: 15X70 | D17: 70 | E17: 15 | F17: 1050 | G17: Gifted | I17: =IF(G17="Unsold",F17,IF(G17="Part-sold",F17-H17,0)) -> 0 | K17: =IF(OR(G17="Sold",G17="Part-sold"),H17*Summary!$B$3,0) -> 0 | M17: =K17-N(L17) -> 0 | N17: =I17*Summary!$B$3 -> 0
A18: 17 | B18: 206 | C18: 15X70 | D18: 70 | E18: 15 | F18: 1050 | G18: Gifted | I18: =IF(G18="Unsold",F18,IF(G18="Part-sold",F18-H18,0)) -> 0 | K18: =IF(OR(G18="Sold",G18="Part-sold"),H18*Summary!$B$3,0) -> 0 | M18: =K18-N(L18) -> 0 | N18: =I18*Summary!$B$3 -> 0
A19: 18 | B19: 206 | C19: 15X70 | D19: 70 | E19: 15 | F19: 1050 | G19: Gifted | I19: =IF(G19="Unsold",F19,IF(G19="Part-sold",F19-H19,0)) -> 0 | K19: =IF(OR(G19="Sold",G19="Part-sold"),H19*Summary!$B$3,0) -> 0 | M19: =K19-N(L19) -> 0 | N19: =I19*Summary!$B$3 -> 0
A20: No number | B20: 206 | C20: Avg(0,18)X70 | D20: 70 | E20: 9 | F20: 630 | G20: Can't be sold | I20: =IF(G20="Unsold",F20,IF(G20="Part-sold",F20-H20,0)) -> 0 | K20: =IF(OR(G20="Sold",G20="Part-sold"),H20*Summary!$B$3,0) -> 0 | M20: =K20-N(L20) -> 0 | N20: =I20*Summary!$B$3 -> 0 | Q20: Marked "Cant be sold" in the Excel of 10 Oct 2026.
A21: OL | B21: 199 | C21: Avg(55,40,18,13)Xavg(0,35) | D21: 31.5 | E21: 17.5 | F21: 551.25 | G21: Can't be sold | I21: =IF(G21="Unsold",F21,IF(G21="Part-sold",F21-H21,0)) -> 0 | K21: =IF(OR(G21="Sold",G21="Part-sold"),H21*Summary!$B$3,0) -> 0 | M21: =K21-N(L21) -> 0 | N21: =I21*Summary!$B$3 -> 0 | Q21: Marked "Cant be sold" in the Excel of 10 Oct 2026.
A22: 19 | B22: 199 | C22: 15XAvg(55, 54) | D22: 54.5 | E22: 15 | F22: 817.5 | G22: Sold | H22: 817 | I22: =IF(G22="Unsold",F22,IF(G22="Part-sold",F22-H22,0)) -> 0 | J22: 2 | K22: =IF(OR(G22="Sold",G22="Part-sold"),H22*Summary!$B$3,0) -> 653600 | L22: 653600 | M22: =K22-N(L22) -> 0 | N22: =I22*Summary!$B$3 -> 0
A23: 20 | B23: 199 | C23: 15XAvg(54, 53.5) | D23: 53.75 | E23: 15 | F23: 806.25 | G23: Sold | H23: 806 | I23: =IF(G23="Unsold",F23,IF(G23="Part-sold",F23-H23,0)) -> 0 | J23: 2 | K23: =IF(OR(G23="Sold",G23="Part-sold"),H23*Summary!$B$3,0) -> 644800 | L23: 644800 | M23: =K23-N(L23) -> 0 | N23: =I23*Summary!$B$3 -> 0
A24: 21 | B24: 199 | C24: 15XAvg(53.5, 53) | D24: 53.25 | E24: 15 | F24: 798.75 | G24: Sold | H24: 795 | I24: =IF(G24="Unsold",F24,IF(G24="Part-sold",F24-H24,0)) -> 0 | J24: 2 | K24: =IF(OR(G24="Sold",G24="Part-sold"),H24*Summary!$B$3,0) -> 636000 | L24: 636000 | M24: =K24-N(L24) -> 0 | N24: =I24*Summary!$B$3 -> 0
A25: 22 | B25: 199 | C25: 15X53 | D25: 53 | E25: 15 | F25: 795 | G25: Sold | H25: 795 | I25: =IF(G25="Unsold",F25,IF(G25="Part-sold",F25-H25,0)) -> 0 | J25: 2 | K25: =IF(OR(G25="Sold",G25="Part-sold"),H25*Summary!$B$3,0) -> 636000 | L25: 636000 | M25: =K25-N(L25) -> 0 | N25: =I25*Summary!$B$3 -> 0
A26: 23 | B26: 199 | C26: 15XAvg(53, 52) | D26: 52.5 | E26: 15 | F26: 787.5 | G26: Sold | H26: 787 | I26: =IF(G26="Unsold",F26,IF(G26="Part-sold",F26-H26,0)) -> 0 | J26: 2 | K26: =IF(OR(G26="Sold",G26="Part-sold"),H26*Summary!$B$3,0) -> 629600 | L26: 629600 | M26: =K26-N(L26) -> 0 | N26: =I26*Summary!$B$3 -> 0
A27: 24 | B27: 199 | C27: 15XAvg(52, 54) | D27: 53 | E27: 15 | F27: 795 | G27: Sold | H27: 795 | I27: =IF(G27="Unsold",F27,IF(G27="Part-sold",F27-H27,0)) -> 0 | K27: =IF(OR(G27="Sold",G27="Part-sold"),H27*Summary!$B$3,0) -> 636000 | L27: 636000 | M27: =K27-N(L27) -> 0 | N27: =I27*Summary!$B$3 -> 0
A28: 25 | B28: 199 | C28: 15XAvg(54, 54.5) | D28: 54.25 | E28: 15 | F28: 813.75 | G28: Sold | H28: 810 | I28: =IF(G28="Unsold",F28,IF(G28="Part-sold",F28-H28,0)) -> 0 | K28: =IF(OR(G28="Sold",G28="Part-sold"),H28*Summary!$B$3,0) -> 648000 | L28: 648000 | M28: =K28-N(L28) -> 0 | N28: =I28*Summary!$B$3 -> 0
A29: 26 | B29: 199 | C29: 15XAvg(54.5, 49) | D29: 51.75 | E29: 15 | F29: 776.25 | G29: Sold | H29: 772 | I29: =IF(G29="Unsold",F29,IF(G29="Part-sold",F29-H29,0)) -> 0 | J29: 4 | K29: =IF(OR(G29="Sold",G29="Part-sold"),H29*Summary!$B$3,0) -> 617600 | L29: 617600 | M29: =K29-N(L29) -> 0 | N29: =I29*Summary!$B$3 -> 0
A30: 27 | B30: 199 | C30: Avg(15,6)XAvg( 49,53) | D30: 51 | E30: 10.5 | F30: 535.5 | G30: Sold | H30: 462 | I30: =IF(G30="Unsold",F30,IF(G30="Part-sold",F30-H30,0)) -> 0 | J30: 4 | K30: =IF(OR(G30="Sold",G30="Part-sold"),H30*Summary!$B$3,0) -> 369600 | L30: 369600 | M30: =K30-N(L30) -> 0 | N30: =I30*Summary!$B$3 -> 0 | Q30: To check: Area corrected from 688.5 to 535.5 sq ft (Excel value did not match its own formula) To check: Sq ft sold on map 27–30 looks shifted by one row; check sale deeds
A31: 28 | B31: 198 | C31: 15X34 | D31: 34 | E31: 15 | F31: 510 | G31: Sold | H31: 462 | I31: =IF(G31="Unsold",F31,IF(G31="Part-sold",F31-H31,0)) -> 0 | J31: 8 | K31: =IF(OR(G31="Sold",G31="Part-sold"),H31*Summary!$B$3,0) -> 369600 | L31: 369600 | M31: =K31-N(L31) -> 0 | N31: =I31*Summary!$B$3 -> 0 | Q31: To check: Sq ft sold on map 27–30 looks shifted by one row; check sale deeds
A32: 29 | B32: 198 | C32: 15XAvg(34, 35) | D32: 34.5 | E32: 15 | F32: 517.5 | G32: Sold | H32: 510 | I32: =IF(G32="Unsold",F32,IF(G32="Part-sold",F32-H32,0)) -> 0 | J32: 8 | K32: =IF(OR(G32="Sold",G32="Part-sold"),H32*Summary!$B$3,0) -> 408000 | L32: 408000 | M32: =K32-N(L32) -> 0 | N32: =I32*Summary!$B$3 -> 0 | Q32: To check: Sq ft sold on map 27–30 looks shifted by one row; check sale deeds
A33: 30 | B33: 198 | C33: 15XAvg(35, 41) | D33: 38 | E33: 15 | F33: 570 | G33: Sold | H33: 517 | I33: =IF(G33="Unsold",F33,IF(G33="Part-sold",F33-H33,0)) -> 0 | J33: 8 | K33: =IF(OR(G33="Sold",G33="Part-sold"),H33*Summary!$B$3,0) -> 413600 | L33: 413600 | M33: =K33-N(L33) -> 0 | N33: =I33*Summary!$B$3 -> 0 | Q33: To check: Sq ft sold on map 27–30 looks shifted by one row; check sale deeds
A34: 31 | B34: 196 | C34: 19XAvg(41,74) | D34: 57.5 | E34: 19 | F34: 1092.5 | G34: Sold | H34: 1092.5 | I34: =IF(G34="Unsold",F34,IF(G34="Part-sold",F34-H34,0)) -> 0 | K34: =IF(OR(G34="Sold",G34="Part-sold"),H34*Summary!$B$3,0) -> 874000 | L34: 0 | M34: =K34-N(L34) -> 874000 | N34: =I34*Summary!$B$3 -> 0 | P34: 2026-03-01 | Q34: Sold in March 2026 (exact date not recorded). Nothing paid to partners yet (per Venu, 17 Oct 2026).
A35: 32 | B35: 196 | C35: 15XAvg(74, 86.5) | D35: 80.25 | E35: 15 | F35: 1203.75 | G35: Sold | H35: 1200 | I35: =IF(G35="Unsold",F35,IF(G35="Part-sold",F35-H35,0)) -> 0 | K35: =IF(OR(G35="Sold",G35="Part-sold"),H35*Summary!$B$3,0) -> 960000 | L35: 960000 | M35: =K35-N(L35) -> 0 | N35: =I35*Summary!$B$3 -> 0
A36: 33 | B36: 196 | C36: 15XAvg(86.5, 101) | D36: 93.5 | E36: 15 | F36: 1402.5 | G36: Sold | H36: 1402 | I36: =IF(G36="Unsold",F36,IF(G36="Part-sold",F36-H36,0)) -> 0 | K36: =IF(OR(G36="Sold",G36="Part-sold"),H36*Summary!$B$3,0) -> 1121600 | L36: 1121600 | M36: =K36-N(L36) -> 0 | N36: =I36*Summary!$B$3 -> 0 | Q36: Excel of 10 Oct 2026 shows the full ₹11,21,600 received.
A37: 34 | B37: 196 | C37: Avg(15,12)Xavg(101,120) | D37: 110.5 | E37: 13.5 | F37: 1492 | G37: Part-sold | H37: 880 | I37: =IF(G37="Unsold",F37,IF(G37="Part-sold",F37-H37,0)) -> 612 | J37: 1 | K37: =IF(OR(G37="Sold",G37="Part-sold"),H37*Summary!$B$3,0) -> 704000 | L37: 604811 | M37: =K37-N(L37) -> 99189 | N37: =I37*Summary!$B$3 -> 489600 | Q37: Sold in parts: 34.1 = 880 sq ft sold; 34.2 = 612 sq ft not sold (Excel of 10 Oct 2026). Part of Tranche 1 (paid as one lump sum; split here by sq ft sold).
A38: 35 | B38: 196 | C38: 15X60 | D38: 60 | E38: 15 | F38: 900 | G38: Sold | H38: 900 | I38: =IF(G38="Unsold",F38,IF(G38="Part-sold",F38-H38,0)) -> 0 | J38: 1 | K38: =IF(OR(G38="Sold",G38="Part-sold"),H38*Summary!$B$3,0) -> 720000 | L38: 618557 | M38: =K38-N(L38) -> 101443 | N38: =I38*Summary!$B$3 -> 0 | Q38: Part of Tranche 1 (paid as one lump sum; split here by sq ft sold).
A39: 36 | B39: 196 | C39: 15X60 | D39: 60 | E39: 15 | F39: 900 | G39: Sold | H39: 900 | I39: =IF(G39="Unsold",F39,IF(G39="Part-sold",F39-H39,0)) -> 0 | J39: 7 | K39: =IF(OR(G39="Sold",G39="Part-sold"),H39*Summary!$B$3,0) -> 720000 | L39: 720000 | M39: =K39-N(L39) -> 0 | N39: =I39*Summary!$B$3 -> 0
A40: 37 | B40: 196 | C40: 15X60 | D40: 60 | E40: 15 | F40: 900 | G40: Sold | H40: 900 | I40: =IF(G40="Unsold",F40,IF(G40="Part-sold",F40-H40,0)) -> 0 | J40: 7 | K40: =IF(OR(G40="Sold",G40="Part-sold"),H40*Summary!$B$3,0) -> 720000 | L40: 720000 | M40: =K40-N(L40) -> 0 | N40: =I40*Summary!$B$3 -> 0
...

Sheet Other payments
A1: Date | B1: Description | C1: Amount (₹) | D1: Notes
B2: Token advance paid by MKR on taking up the development agreement | C2: 2000000 | D2: ₹5,00,000 per partner. Not tied to any plot (per Venu, 17 Oct 2026).
A4: Payments by MKR to the partners that are not tied to a plot (for example the token advance). Add one row per payment.

Sheet How to update
A1: How to update this ledger
A2: 1. Change only the blue cells on the Plots sheet: status, sq ft sold, paid to partners, buyer, sale date, notes.
A3: 2. Status must be one of: Sold, Part-sold, Unsold, Gifted, Can't be sold.
A4: 3. When MKR hands over money for a plot, add it to "Paid to partners" for that plot.
A5: 4. Money not tied to a plot (such as the token advance) goes on the "Other payments" sheet, one row per payment.
A6: 5. Keep the file name ledger.xlsx and upload it to the GitHub repository (Add file → Upload files). The website updates itself in a minute or two.
A7: Do not rename sheets or column headings; the website reads them by name.
